Workbook

Sheet START HERE
A1: MUNSTER LOGISTICS LLC - LOAD DESK - Wed 9 Sep 2026
A2: Justin Munster | MC-84057665 | USDOT 7555217 | Domicile New Richmond, OH 45157 | Built from 123Loadboard pulls dated Sep 8 and Sep 9, 2026
B4: THE TRUCK - read this out loud on every call
B5: Carrier | C5: Munster Logistics LLC - MC-84057665, USDOT 7555217
B6: Deck | C6: 30 ft gooseneck (25 ft + 5 ft), 102 in wide, approx 34 in deck height
B7: Max payload | C7: 9,000 lbs - HARD CEILING
B8: Hard reject rule | C8: Anything over 30 ft OR over 9,000 lbs = automatic no. Do not bid it.
B9: Securement | C9: Flat tarps, Grade 80 chains and binders, straps, mega ramps on board
B10: Insurance | C10: $1M auto liability, $100k cargo
B11: Home base | C11: New Richmond, OH 45157
B12: Hours rule | C12: Weekdays overnight OK. Weekends he must be home. (Owner rule, 28 Aug 2026)
B13: Authority age | C13: MC granted 7 Aug 2026. 180-day mark lands approx 3 Feb 2027.
B15: THE ONE QUESTION THAT SAVES THE MOST TIME
B16: Ask in the FIRST 30 SECONDS of every single call: "Do you have a new-authority rule, and how many days?" Munster's authority was granted 7 Aug 2026. Any broker running a 180-day rule structurally CANNOT use this truck until roughly 3 Feb 2027 (Sureway/ATS confirmed exactly this on 24 Aug, and said a Highway packet does not roll over for a new authority either). Asking it first turns a four-minute hold into a ten-second disqualifier. Log the answer in the BROKER CRM tab - it never has to be asked twice.
B20: WHAT WAS APPLIED TO THIS SHORTLIST - your two answers
B21: Weekend rule | C21: STRICT. Only runs that deliver AND get him home by Fri 11 Sep night are shortlisted. Idaho and Maine went to REJECTED with the reason written out.
B22: Rate floor | C22: $2.00 per mile ALL-IN, i.e. deadhead miles + loaded miles. That is the real number he earns. Every load also shows loaded-only RPM so you can see both.
B23: Availability | C23: Justin is free from Wed 9 Sep. Backhaul: YES.
B25: THE ONE THING TO CHECK BEFORE ANY OF THIS IS REAL
B26: ONE load - L10, Freightwatch, Lexington OH to Channahon IL - is genuinely posted for a Sep 9 pickup. It is the only one with no rolling risk, and that is why it sits at rank 1. EVERY OTHER load here was posted for Sep 8, so the first thing on those calls is: "Is this still available, and can it pick up tomorrow?" L3, L6 and L9 carry a hard 12:00 PM Sep 8 appointment - the highest-risk group. Nothing here is a booking. Nothing was sent to any broker. Every message and call goes out from you.
B29: HOW TO READ THIS FILE
B30: Blue text cells | C30: You edit these. Target Ask, Walk-away, the 1-5 judgement scores, and everything in BROKER CRM / CALL LOG. Everything else recalculates itself.
B31: Yellow cells | C31: Assumptions that are NOT verified data (fuel price, MPG). Put Justin's real numbers in and the whole sheet updates.
B32: Blank / n/a | C32: Means genuinely unknown - it was not on the board and was not invented. Where a call is needed to fill it, the sheet says so.
B33: SHORTLIST | C33: Ranked call order. Change a Target Ask and the score, RPM and net re-rank in real time.
B34: RATE CALC | C34: Type any load's miles and any offer to see instantly whether it clears the floor.
B35: BROKER CRM | C35: One row per broker: contacts, what was said last time, how many times, when to chase next.
B36: CALL LOG | C36: Append-only history. The 24-25 Aug calls are already in there.
B37: COPY DECK | C37: THIS is the tab to copy from. Every message and email, one line per ROW, with the exact row numbers to select. Copying a whole message out of a single cell is what adds quote marks - this tab avoids that.
B38: MESSAGES + EMAILS | C38: Overview of the same messages: which channels each posting offers, the bid amount, how to play it. Read here, copy from COPY DECK.
B39: CALL SCRIPTS | C39: Word-for-word phone script, voicemail and email per broker. Drafts only - you send.
B40: ANALYSIS | C40: The charts: RPM against the floor, deadhead burden, and where the money actually is.

Sheet SAY THIS NOW
A1: SAY THIS NOW - Tuesday 8 Sep, word for word
A2: Left column is what you say, out loud, in this order. Right column is why that line is there, so you can hold your ground when they push.
B4: SAY THIS (word for word) | C4: WHY THIS LINE IS HERE
B5: THE GATE - ask this FIRST on every call from now on
B6: Both of today's best loads were lost to onboarding rules, not rate. Never discuss a rate before this is answered. | C6: Venture's bot haggled price for twelve hours on loads their compliance side could never have set us up for. Freightwatch blocked us on a 1-year rule. Ten seconds of qualifying would have saved the whole night.
B7: "Hi, this is Yaseen with Munster Logistics, MC 84057665 - 30 foot hotshot gooseneck out of New Richmond, Ohio." | C7: Name, MC, equipment. They know instantly you are a real carrier.
B8: "Before we talk about any load, two quick qualifying questions so I don't waste your time." | C8: Framing it as saving THEIR time is why nobody minds being asked.
B9: "Do you have a minimum time-in-business or new-authority requirement? Ours was granted 7 August this year." | C9: Freightwatch wanted 1 year. Sureway wanted 180 days. This is the single most common wall for a 32-day-old authority.
B10: "And do you accept Progressive insurance? We carry $1M auto liability and $100k cargo." | C10: Venture refused on exactly this. Rare, but it costs nothing to ask and it ends the call early when it is a no.
B11: IF EITHER IS A NO -> "Understood, thanks for telling me straight. When does that open up for us?" Write the date down. | C11: A clean early no is worth more than a long maybe. And the date tells you when to come back.
B12: THEN ALWAYS ASK THIS -> "Last thing, and I'd really appreciate it - who do you know that DOES work with newer authorities? Any broker or agent you'd point me at?" | C12: This is the highest-value sentence of a losing call. Brokers all know each other, they lose nothing by naming one, and most people want to be helpful after saying no. It turns a dead end into a lead - and right now leads are worth more than loads.
B13: IF BOTH ARE YES -> now, and only now, talk about the load. | C13: From here the rate conversation is real, because they can actually use you.
B15: CALL NOW - FIFTH WHEEL FREIGHT (616) 965-7277 ext 8530
B16: They did not answer at 08:10. On 24 Aug the live person came later in the morning, so keep trying to about 09:00. | C16: This is still the highest-value relationship on the board - they post more Munster-sized hotshot freight than anyone else.
B17: [THE GATE - both questions above, before anything else.] | C17: They transferred straight to compliance on 24 Aug, which means they do screen. Find out now.
B18: "I'm on your reference 758397, Huntington West Virginia to Sparrows Point Maryland - 11 feet, 6,000 pounds. Is it still open, and can it load tomorrow the 9th?" | C18: Justin is free from tomorrow, and this was posted for the 8th.
B19: "It's posted at $900. I've got 106 miles of deadhead just to reach Huntington, so that's 523 total miles - $1.72 a mile, and I can't cover the truck at that. At $1,300 I'll take it." | C19: Same arithmetic as always: the empty miles to the shipper are real and they are yours.
B20: WALK AWAY AT $1,075. | C20: Below that it stops clearing $2.00 a mile all-in.
B21: "Yes, we'll accept MacroPoint - confirm the number it should go to." | C21: Their posting requires it. Saying yes before they ask removes an objection.
B22: "And while I have you - extension 8550 has reference 757767, Fort Wayne to Cedar Point Kansas. $1,400 doesn't work; Cedar Point leaves me empty a long way. At $2,000 I'll cover it." | C22: ONE call, BOTH loads. Do not ring them twice - it wastes their time and yours.
B23: "Last thing - can you get our truck on your list? 30 foot deck, 9,000 pounds, tarps and Grade 80 on board, empty out of Cincinnati most weekday mornings." | C23: This sentence is worth more than either load. They post this size of freight constantly.
B25: 09:00 ET - TRANSPORTATION EXPRESS (402) 564-6375 (Nebraska, 08:00 there)
B26: "Hi, this is Yaseen with Munster Logistics. Back on the 24th of August someone there asked us to have a live person call - and that call never came. That's on us, and I'm the live person. I'm sorry it took this long." | C26: Open by owning it. A human there asked for a human and got silence - this is the sentence that reopens the door.
B27: [THEN THE GATE - time-in-business, and Progressive.] | C27: Even on a repair call, qualify before you quote.
B28: "You've got Piqua Ohio to Pineville North Carolina, 4 feet and 2,900 pounds. Is it still open for a Wednesday pickup? There's no rate on the posting - what are you paying on it?" | C28: No rate is published, so ask and then STAY QUIET. Let them name a number first.
B29: "That's only 4 feet of my 30 foot deck. If you've got a second partial going the same direction I'll take both on one truck - cheaper for you than two carriers. Piqua is only 82 miles from me so I can be there early." | C29: Lowest deadhead on the whole board, and a 30 ft deck carrying 4 ft is mostly empty. Two partials is a real offer, not a pitch.
B30: TARGET $1,300. WALK AWAY AT $1,150. | C30: 581 total miles. $1,150 is roughly break-even at $2.00 all-in.
B32: 09:00 ET - JOE TEX, INC. (903) 537-7100 (Texas, 08:00 there)
B33: "Hi, could I speak with Angie please?" | C33: ASK FOR HER BY NAME. Two calls have already died in this company's IVR - working the menu has failed twice.
B34: [THEN THE GATE - time-in-business, and Progressive.]
B35: "I'm looking at reference 519281, Muncie Indiana to Decatur Illinois - 20 feet, 8,000 pounds. Is it still open for a Wednesday pickup, and is 8,000 pounds the real weight? My hard ceiling is 9,000." | C35: 8,000 is close to the limit. Confirm it before agreeing anything - an overweight surprise at the shipper is a wasted day.
B36: "There's no rate posted - what are you paying? ... It's 109 miles of deadhead to Muncie and 215 loaded, so 324 total. I need $850 to make that work." | C36: Short run, so the deadhead is a big share of it - 109 empty miles against 215 paid.
B37: WALK AWAY AT $675. | C37: 324 total miles at $2.00 all-in is $650.
B38: "One admin point - our records show a 'Joe Tex LLC' and the board says 'Joe Tex, Inc.' Same company?" | C38: Worth ten seconds so the CRM is filed under the right name.
B40: ANY TIME - RELATIONSHIP CALLS, no load attached
B41: WHITEWATER FREIGHT (812) 637-1720 - [THE GATE], then: "I'm not calling about a specific load. You post partials regularly and that's exactly what this truck is built for - 10 to 30 feet, up to 9,000 pounds, empty out of Cincinnati most weekday mornings. Can you put us on your list, and what does your setup packet need?" | C41: Their Maine load is priced wrong, but the broker TYPE is a very good match. Play the relationship, not the load.
B42: WARREN TRANSPORT (800) 206-7980 - "Your posting 1181425 shows no length and no weight. What are they actually? We run a 30 foot deck at 9,000 pounds max." | C42: Lowest priority. The Idaho run breaks the weekend-home rule anyway - this is one question, not a pitch.
B44: AFTER EVERY CALL - three things
B45: Who you spoke to · what they said about the GATE (time-in-business + Progressive) · any rate they named. | C45: The gate answers are now the most valuable thing you can collect. They are permanent - a broker's onboarding rule does not change week to week, so every answer saves a future call.
B46: And it is fine if today produces no load. | C46: Two doors shut on onboarding rules, not on anything you did. A 32-day-old authority hits this wall - it was written down on 24 August. What today buys is a map of who can actually use this truck.

Sheet SHORTLIST
A1: SHORTLIST - call these, in this order
A2: Strict weekend-home rule applied | $2.00/mi ALL-IN floor | Every load below fits the 30 ft / 9,000 lb deck | L10 is a real Sep 9 pickup - the other six are Sep 8 postings that must be talked into rolling a day
A4: Rank | B4: Score | C4: ID | D4: Broker | E4: Origin | F4: Destination | G4: Pickup | H4: Appt | I4: DH mi | J4: Loaded mi | K4: Total mi | L4: Equip | M4: Size | N4: Len ft | O4: Weight lbs | P4: Posted $ | Q4: Posted $/mi (loaded) | R4: 123LB Rate Check $ | S4: Floor ask @ $2.00 all-in | T4: TARGET ASK $ | U4: Walk-away $ | V4: All-in $/mi at target | W4: Loaded $/mi at target | X4: Est. fuel $ | Y4: Net after fuel $ | Z4: Backhaul 1-5 | AA4: Relationship 1-5 | AB4: Timing risk 1-5 | AC4: Fit check | AD4: Why it made the list / watch-outs | AE4: First question on the call
A5: =RANK(B5,$B$5:$B$11,0) -> 1 | B5: =ROUND(30*MIN(V5/2.5,1)+20*MIN(Y5/2500,1)+5*Z5+3*AA5+2*(6-AB5),0) -> 80 | C5: L10 | D5: Freightwatch, LLC | E5: Lexington, OH | F5: Channahon, IL | G5: Sep 9 | I5: 146 | J5: 367 | K5: =I5+J5 -> 513 | L5: Flatbed (Hot shot) | M5: TL | O5: 4700 | P5: 800 | Q5: =IF(OR(P5="",J5=0),"",P5/J5) -> 2.1798365 | R5: 1287 | S5: =ROUNDUP(K5*'RATE CALC'!$C$5/25,0)*25 -> 1050 | T5: 1300 | U5: 1050 | V5: =IF(K5=0,"",T5/K5) -> 2.5341131 | W5: =IF(J5=0,"",T5/J5) -> 3.5422343 | X5: =IF('RATE CALC'!$C$6=0,"",K5/'RATE CALC'!$C$6*'RATE CALC'!$C$7) -> 189.81 | Y5: =T5-X5 -> 1110.19 | Z5: 5 | AA5: 2 | AB5: 1 | AC5: DEAD 8 Sep - broker will not work with a carrier under 1 year in business. Nothing to do with the truck. | AD5: BLOCKED ON 8 SEP: Freightwatch said by phone they do not onboard carriers under one year in business. Munster's authority is 32 days old, so this is shut until roughly 7 Aug 2027. Everything below was true and is why it hurts - the rate was never the problem. The only load on the board posted for Sep 9, so there was no 'will it roll?' risk at all - this is the one that matches Justin's availability exactly. Channahon IL sits in the Chicago metro, which is the strongest backhaul market on this list and already a saved search (MUNSTER BACK-CHI). Delivers Sep 10, home well before Saturday. Posted $800 = $1.56/mi all-in, under floor, but 123LB's own Rate Check says $1,287 so the money is there. THE ONE RISK: a steel stair system with no length posted could easily run past 30 ft - that question decides everything. | AE5: Steel stair system ki overall LENGTH kya hai? Posting par blank hai aur mera deck 30 ft ka hai.
A6: =RANK(B6,$B$5:$B$11,0) -> 5 | B6: =ROUND(30*MIN(V6/2.5,1)+20*MIN(Y6/2500,1)+5*Z6+3*AA6+2*(6-AB6),0) -> 70 | C6: L3 | D6: Venture Connect LLC | E6: Shelbyville, IN | F6: Stanhope, NJ | G6: Sep 8 | H6: 12:00 PM | I6: 92 | J6: 655 | K6: =I6+J6 -> 747 | L6: Flatbed (Hot shot) | M6: TL | N6: 30 | O6: 1095 | P6: 1400 | Q6: =IF(OR(P6="",J6=0),"",P6/J6) -> 2.1374046 | R6: 3235 | S6: =ROUNDUP(K6*'RATE CALC'!$C$5/25,0)*25 -> 1500 | T6: 1600 | U6: 1500 | V6: =IF(K6=0,"",T6/K6) -> 2.1419009 | W6: =IF(J6=0,"",T6/J6) -> 2.4427481 | X6: =IF('RATE CALC'!$C$6=0,"",K6/'RATE CALC'!$C$6*'RATE CALC'!$C$7) -> 276.39 | Y6: =T6-X6 -> 1323.61 | Z6: 4 | AA6: 4 | AB6: 5 | AC6: DEAD 8 Sep - Venture will not set up a carrier insured by Progressive. Truck and schedule are irrelevant now. | AD6: DEAD 8 Sep: Venture said by phone they cannot set Munster up because the insurance is PROGRESSIVE. Everything below happened before that was known, and is kept because of what it teaches: their automated layer negotiated price for twelve hours on a load the company could never have given us. HISTORY: Two replies came back from loads@ventureconnect.mail.parade.ai. Both held at $1,400 ('I've got some lower offers' then 'Load's getting a lot of attention'), both repeated the SAME confirmation block word for word, and both ignored every question asked. That address is Parade, a broker automation platform - this is an automated quoting channel, so it can move a price and nothing else. It cannot move an appointment and it cannot tell you the fine amount. THE CLOCK IS THE REAL BLOCKER: pickup 09/08 1200 EDT, deliver 09/09 0800-1000 EDT, 655 loaded mi. At the ~53 mph 123Loadboard's own postings imply that is 12.4 h driving, over the 11-hour solo limit, so it splits with a 10-hour break and arrival lands at roughly pickup + 23 h = about 1050, missing the window by ~50 minutes. $1,400 over 747 total mi is $1.87/mi all-in, under floor, before PA Turnpike tolls. RECOMMENDATION: do not accept by email. Either phone (317) 854-5027 and get a human to move the pickup to 1100 (or delivery to 1100-1200) AND put the fine amount in writing, or let it go and put the time into L10. | AE6: PHONE ONLY from here: (317) 854-5027 - pickup 1100 tak move hogi? Fine kitne ka hai? Email par ye jawab nahi milenge.
A7: =RANK(B7,$B$5:$B$11,0) -> 2 | B7: =ROUND(30*MIN(V7/2.5,1)+20*MIN(Y7/2500,1)+5*Z7+3*AA7+2*(6-AB7),0) -> 78 | C7: L6 | D7: Fifth Wheel Freight | E7: Huntington, WV | F7: Sparrows Point, MD | G7: Sep 8 | H7: 12:00 PM | I7: 106 | J7: 417 | K7: =I7+J7 -> 523 | L7: Step deck | M7: LTL | N7: 11 | O7: 6000 | P7: 900 | Q7: =IF(OR(P7="",J7=0),"",P7/J7) -> 2.1582734 | S7: =ROUNDUP(K7*'RATE CALC'!$C$5/25,0)*25 -> 1050 | T7: 1300 | U7: 1075 | V7: =IF(K7=0,"",T7/K7) -> 2.4856597 | W7: =IF(J7=0,"",T7/J7) -> 3.117506 | X7: =IF('RATE CALC'!$C$6=0,"",K7/'RATE CALC'!$C$6*'RATE CALC'!$C$7) -> 193.51 | Y7: =T7-X7 -> 1106.49 | Z7: 4 | AA7: 5 | AB7: 4 | AC7: FITS - 11 ft, 6,000 lbs on a 30 ft deck | AD7: Fifth Wheel is the #1 relationship to build (22 Aug: posts the most Munster-sized hotshot freight). Short 417 mi run, Baltimore is a live backhaul market, home well before the weekend. Posted $900 = $1.72/mi all-in, under floor - rate has to move. MacroPoint tracking required. | AE7: Ext 8530 - kal Sep 9 pickup chalegi? Aur aapka new-authority rule kitne din ka hai?
A8: =RANK(B8,$B$5:$B$11,0) -> 3 | B8: =ROUND(30*MIN(V8/2.5,1)+20*MIN(Y8/2500,1)+5*Z8+3*AA8+2*(6-AB8),0) -> 77 | C8: L1 | D8: Transportation Express American Motorways Inc. | E8: Piqua, OH | F8: Pineville, NC | G8: Sep 8 | I8: 82 | J8: 499 | K8: =I8+J8 -> 581 | L8: Flatbed / Step deck | M8: LTL | N8: 4 | O8: 2900 | Q8: =IF(OR(P8="",J8=0),"",P8/J8) | S8: =ROUNDUP(K8*'RATE CALC'!$C$5/25,0)*25 -> 1175 | T8: 1300 | U8: 1150 | V8: =IF(K8=0,"",T8/K8) -> 2.2375215 | W8: =IF(J8=0,"",T8/J8) -> 2.6052104 | X8: =IF('RATE CALC'!$C$6=0,"",K8/'RATE CALC'!$C$6*'RATE CALC'!$C$7) -> 214.97 | Y8: =T8-X8 -> 1085.03 | Z8: 4 | AA8: 5 | AB8: 3 | AC8: FITS - only 4 ft / 2,900 lbs, huge deck left over | AD8: RELATIONSHIP REPAIR: 24 Aug a human here asked 'can you have a live person call me?' and nobody ever called back. This is the call to fix that. Lowest deadhead on the board (82 mi). Only 4 ft of deck used, so it can be co-loaded with a second partial. Rate is NOT posted - it must be asked for. | AE8: 24 August ko aap ne live person maanga tha - main woh person hoon, maaf kijiye der ke liye. Rate kya hai is load par?
A9: =RANK(B9,$B$5:$B$11,0) -> 4 | B9: =ROUND(30*MIN(V9/2.5,1)+20*MIN(Y9/2500,1)+5*Z9+3*AA9+2*(6-AB9),0) -> 74 | C9: L7 | D9: Joe Tex, Inc. | E9: Muncie, IN | F9: Decatur, IL | G9: Sep 8 | I9: 109 | J9: 215 | K9: =I9+J9 -> 324 | L9: Flatbed | M9: LTL | N9: 20 | O9: 8000 | Q9: =IF(OR(P9="",J9=0),"",P9/J9) | S9: =ROUNDUP(K9*'RATE CALC'!$C$5/25,0)*25 -> 650 | T9: 850 | U9: 675 | V9: =IF(K9=0,"",T9/K9) -> 2.6234568 | W9: =IF(J9=0,"",T9/J9) -> 3.9534884 | X9: =IF('RATE CALC'!$C$6=0,"",K9/'RATE CALC'!$C$6*'RATE CALC'!$C$7) -> 119.88 | Y9: =T9-X9 -> 730.12 | Z9: 4 | AA9: 4 | AB9: 3 | AC9: DEAD 8 Sep - Joe Tex requires 6 months in business. Opens ~7 Feb 2027. | AD9: BLOCKED 8 Sep on a 6-month time-in-business rule - the same wall as Sureway's 180 days, and it lands on the same date. HISTORY, all still true for February: short 215 mi hop, easily a same-day. Decatur IL feeds both saved backhaul searches (BACK-CHI and BACK-IND). Rate NOT posted. Riley died in this broker's IVR twice (24 Aug and a queued 25 Aug call) - a human dialling and asking for Angie by name is the whole unlock. Weight is close to the ceiling: confirm 8,000 lbs is the real number. | AE9: Angie se baat karni hai - Muncie to Decatur load par rate kya hai, aur 180-day rule?
A10: =RANK(B10,$B$5:$B$11,0) -> 6 | B10: =ROUND(30*MIN(V10/2.5,1)+20*MIN(Y10/2500,1)+5*Z10+3*AA10+2*(6-AB10),0) -> 69 | C10: L9 | D10: Fifth Wheel Freight | E10: Fort Wayne, IN | F10: Cedar Point, KS | G10: Sep 8 | H10: 12:00 PM | I10: 153 | J10: 758 | K10: =I10+J10 -> 911 | L10: Flatbed (Hot shot) | M10: LTL | N10: 14 | O10: 6033 | P10: 1400 | Q10: =IF(OR(P10="",J10=0),"",P10/J10) -> 1.8469657 | S10: =ROUNDUP(K10*'RATE CALC'!$C$5/25,0)*25 -> 1825 | T10: 2000 | U10: 1850 | V10: =IF(K10=0,"",T10/K10) -> 2.1953897 | W10: =IF(J10=0,"",T10/J10) -> 2.6385224 | X10: =IF('RATE CALC'!$C$6=0,"",K10/'RATE CALC'!$C$6*'RATE CALC'!$C$7) -> 337.07 | Y10: =T10-X10 -> 1662.93 | Z10: 2 | AA10: 5 | AB10: 4 | AC10: FITS - 14 ft, 6,033 lbs | AD10: Only reason it is on the list is Fifth Wheel relationship value. Posted $1,400 = $1.54/mi all-in, well under floor. Cedar Point KS is rural - the backhaul out of there is thin, so the rate has to carry the empty miles home. Take it only if they move to $2,000+. | AE10: Ext 8550 - $1,400 Kansas ke liye kaam nahi karta, $2,000 par kya khayal hai?
A11: =RANK(B11,$B$5:$B$11,0) -> 7 | B11: =ROUND(30*MIN(V11/2.5,1)+20*MIN(Y11/2500,1)+5*Z11+3*AA11+2*(6-AB11),0) -> 68 | C11: L4 | D11: Venture Connect LLC | E11: Shelbyville, IN | F11: Selmer, TN | G11: Sep 8 | I11: 92 | J11: 417 | K11: =I11+J11 -> 509 | L11: Flatbed (Hot shot) | M11: LTL | N11: 20 | O11: 1000 | P11: 900 | Q11: =IF(OR(P11="",J11=0),"",P11/J11) -> 2.1582734 | S11: =ROUNDUP(K11*'RATE CALC'!$C$5/25,0)*25 -> 1025 | T11: 1150 | U11: 1025 | V11: =IF(K11=0,"",T11/K11) -> 2.259332 | W11: =IF(J11=0,"",T11/J11) -> 2.7577938 | X11: =IF('RATE CALC'!$C$6=0,"",K11/'RATE CALC'!$C$6*'RATE CALC'!$C$7) -> 188.33 | Y11: =T11-X11 -> 961.67 | Z11: 3 | AA11: 4 | AB11: 3 | AC11: DEAD 8 Sep - same as L3. Venture refused on Progressive insurance, so the carrier was never eligible. | AD11: DEAD 8 Sep on the same Progressive refusal as L3. Kept because the analysis was right and will apply to the next load like it. HISTORY: the clock on this one actually worked, unlike L3. Broker confirmed 8 Sep: pickup Shelbyville 09/08 between 1100 and 1400 EDT (a three-hour WINDOW, not a fixed appointment), delivery Selmer TN 09/09 between 0800 and 1000 CDT - and Central time gives back an hour. 417 loaded mi is 8h50m by the board's own figure, so no 11-hour problem on the load itself; even at the latest 1400 pickup he arrives Selmer around 2220 CDT and waits overnight for the window. He can also split it 8 h / 10 h off / finish in the morning and land about 0635 CDT with plenty of margin. TWO REAL CATCHES: (1) 92 mi deadhead plus 417 loaded is 10.78 h total driving - only 13 minutes under the 11-hour limit if he runs it in one shift, so any hold-up at loading forces the split; (2) $900 over 509 total mi is $1.77/mi all-in, under floor - it needs $1,025 just to reach $2.00. Note this posting has NO tracking requirement, unlike L3. 8 Sep UPDATE: countered at $1,150 and the bot came back holding at $900 (its words: other offers lower than that, meet me at $900 and it is yours). It has not moved and it has now ignored the fine question four times across both loads. AT $900 THIS IS $1.77/mi ALL-IN - $125 under break-even, netting roughly $712 before tolls for a day and a half with an overnight - and it carries an unquantified late-delivery fine on a jobsite. Compare L10: near-identical 513 total miles, $1,300, a Sep 9 pickup, no fine at all. | AE11: Fine kitne ka hai? Ye char dafa poocha ja chuka hai aur jawab nahi aaya - price se pehle YEHI chahiye.
C13: REJECTED - and exactly why
C14: ID | D14: Broker | E14: Lane | F14: Total mi | G14: Posted $ | H14: All-in $/mi at posted | I14: Verdict | J14: Reason - the honest version
C15: L2 | D15: Warren Transport, Inc. | E15: Union City, IN -> Heyburn, ID | F15: 1867 | H15: =IF(OR(G15="",G15=0),"not posted",G15/F15) -> not posted | I15: NO - weekend-home rule + spec unconfirmed | J15: 1,775 mi one-way to Idaho. Leaving Wed 9 Sep he cannot deliver and be home by Saturday - that breaks the 28 Aug rule (weekdays overnight OK, weekends must be home). Also: the board shows length and weight as BLANK, and a TL flatbed at 15 pieces is almost certainly a 48/53 ft trailer load, not a 30 ft deck. Market $4,818 / $2.71 per mi is the best gross on the board - if the weekend rule ever flexes, this is the one to re-open, but ONLY after confirming length and weight.
C16: L5 | D16: Fenichey LLC | E16: Louisville, KY -> Newington, CT | F16: 965 | G16: 2900 | H16: =IF(OR(G16="",G16=0),"not posted",G16/F16) -> 3.0051813 | I16: HARD NO - truck spec | J16: Load note is explicit: 'Dedicated 48 or 53' stepdeck with chains and straps required' plus FULL TARPING. Justin runs a 30 ft gooseneck deck. This is an automatic reject regardless of the $2,900 / $3.34 per mi. Do not bid.
C17: L8 | D17: Whitewater Freight Inc | E17: Pandora, OH -> Easton, ME | F17: 1261 | G17: 1850 | H17: =IF(OR(G17="",G17=0),"not posted",G17/F17) -> 1.4670896 | I17: NO - rate + dead-end backhaul + weekend | J17: Fits the deck (15 ft / 750 lbs) but $1,850 over 1,261 total miles is $1.47/mi all-in, far under the $2.00 floor. Easton ME is deep north-east Maine - one of the worst backhaul markets in the country, so the empty miles home are on Justin. And it cannot be delivered and back before Saturday. Would need roughly $2,525 just to hit the floor before the empty return is even counted.

Sheet RATE CALC
A1: RATE CALCULATOR - live
A2: Change any blue cell. Everything else updates instantly. Yellow = assumption, replace with Justin's real numbers.
B4: GLOBAL SETTINGS
B5: Rate floor ($ per mile, ALL-IN) | C5: 2 | D5: Your instruction, 8 Sep 2026. Matches Munster's 123LB truck post #6978096 ($2.00/mi).
B6: Truck MPG (loaded) | C6: 10 | D6: ASSUMPTION - not verified. Put Justin's real loaded MPG here.
B7: Diesel price ($ per gallon) | C7: 3.7 | D7: ASSUMPTION - not verified. Put today's real pump price here.
B10: WHAT-IF: is this offer any good?
B11: Deadhead mi | C11: Loaded mi | D11: Total mi | E11: Offer on the table $ | F11: All-in $/mi | G11: Loaded $/mi | H11: Est. fuel $ | I11: Net after fuel $ | J11: Verdict
B12: 92 | C12: 655 | D12: =B12+C12 -> 747 | E12: 1400 | F12: =IF(D12=0,"",E12/D12) -> 1.8741633 | G12: =IF(C12=0,"",E12/C12) -> 2.1374046 | H12: =IF(OR(D12=0,'RATE CALC'!$C$6=0),"",D12/'RATE CALC'!$C$6*'RATE CALC'!$C$7) -> 276.39 | I12: =IF(E12="","",E12-H12) -> 1123.61 | J12: =IF(E12="","",IF(F12>='RATE CALC'!$C$5,"CLEARS THE FLOOR","BELOW FLOOR - need "&TEXT(ROUNDUP(D12*'RATE CALC'!$C$5/25,0)*25,"$#,##0"))) -> BELOW FLOOR - need $1,500
B15: Reminder: the floor is measured on TOTAL miles (deadhead + loaded), because that is what the truck actually turns. A load that looks like $2.16/mi on loaded miles alone can still be $1.72/mi in real life once the empty run to the shipper is counted.

Sheet ALL LOADS
A1: ALL 10 LOADS - exactly as the board showed them
A2: 123Loadboard pulls, Sep 8 and Sep 9 2026. Nothing added, nothing guessed. A blank cell means the board did not show a value - L2's length and weight and L10's length really are blank on the posting.
A4: ID | B4: Broker | C4: Origin | D4: Deadhead mi | E4: Destination | F4: Pickup | G4: Appt | H4: Distance mi | I4: Driving time | J4: Trailer type | K4: Load size | L4: Length ft | M4: Weight lbs | N4: Posted rate $ | O4: Posted $/mi | P4: 123LB Rate Check $ | Q4: Rate Check $/mi | R4: Item | S4: Ref # | T4: Contact name | U4: Email | V4: Phone | W4: Contact options on the posting | X4: Load note (verbatim)
A5: L1 | B5: Transportation Express American Motorways Inc. | C5: Piqua, OH | D5: 82 | E5: Pineville, NC | F5: Sep 8 | H5: 499 | I5: 9h 22m | J5: Flatbed / Step deck | K5: LTL | L5: 4 | M5: 2900 | T5: Dispatch | V5: (402) 564-6375 | W5: Phone only (no Message / Bid / email on the posting) | X5: CALL
A6: L2 | B6: Warren Transport, Inc. | C6: Union City, IN | D6: 92 | E6: Heyburn, ID | F6: Sep 8 | H6: 1775 | I6: 32h 44m | J6: Flatbed | K6: TL | P6: 4818 | Q6: 2.71 | S6: 1181425 | T6: Angie, Erica, Michele, Ken | U6: loads@warrentransport.com | V6: (800) 206-7980 | W6: Phone + Email + Message (no Bid) | X6: Flat w/ tarps or conestoga. Qty 15.
A7: L3 | B7: Venture Connect LLC | C7: Shelbyville, IN | D7: 92 | E7: Stanhope, NJ | F7: Sep 8 | G7: 12:00 PM | H7: 655 | J7: Flatbed (Hot shot) | K7: TL | L7: 30 | M7: 1095 | N7: 1400 | O7: 2.14 | P7: 3235 | Q7: 4.94 | R7: CONSTRUCTION MATERIALS | S7: 2177463-2099008 | T7: Dispatch | U7: loadpostings+123lb@venturelogistics.com | V7: (317) 854-5027 | W7: Phone + Email + Message + BID | X7: FINES FOR LATE DELIVERY. 27 ft of space. Check in 30 min prior. NO TARPS. Jobsite - check in with broker name TRANSCOR / pickup number. Hard hat, hi-viz vest, closed-toe shoes. Tracking Required = True. Deliver Sep 9.
A8: L4 | B8: Venture Connect LLC | C8: Shelbyville, IN | D8: 92 | E8: Selmer, TN | F8: Sep 8 | H8: 417 | I8: 8h 50m | J8: Flatbed (Hot shot) | K8: LTL | L8: 20 | M8: 1000 | N8: 900 | O8: 2.16 | R8: CONSTRUCTION MATERIALS | S8: 2178262-2099817 | T8: Dispatch | U8: loadpostings+123lb@venturelogistics.com | V8: (317) 854-5027 | W8: Phone + Email + Message + BID | X8: FINES FOR LATE DELIVERY. 20 ft of space. NO TARPS. Jobsite - check in with broker name TRANSCOR / pickup number. Hard hat, hi-viz, closed-toe shoes. Deliver Sep 9.
A9: L5 | B9: Fenichey LLC | C9: Louisville, KY | D9: 97 | E9: Newington, CT | F9: Sep 8 | H9: 868 | J9: Step deck | K9: TL | M9: 3351 | N9: 2900 | O9: 3.34 | R9: Machinery or Machine Parts | S9: 140339 | T9: Dispatch | U9: boardresponse+123lb@fenichey.com | V9: (475) 445-2870 | W9: Phone + Email + Message + BID | X9: Dedicated 48 or 53' stepdeck with chains and straps REQUIRED. Full tarping required. Chain tracking must be active at all times - deductions if disabled. Delivery on or by 9/10 by 3pm.
A10: L6 | B10: Fifth Wheel Freight | C10: Huntington, WV | D10: 106 | E10: Sparrows Point, MD | F10: Sep 8 | G10: 12:00 PM | H10: 417 | J10: Step deck | K10: LTL | L10: 11 | M10: 6000 | N10: 900 | O10: 2.16 | S10: 758397 | T10: Dispatch (ext. 8530) | V10: (616) 965-7277 | W10: Phone only (no Message / Bid / email on the posting) | X10: CALL ext. 8530 with any questions. Load must be fully secured before and upon delivery. Driver must accept MacroPoint.
A11: L7 | B11: Joe Tex, Inc. | C11: Muncie, IN | D11: 109 | E11: Decatur, IL | F11: Sep 8 | H11: 215 | I11: 4h 27m | J11: Flatbed | K11: LTL | L11: 20 | M11: 8000 | S11: 519281 | T11: Angie | V11: (903) 537-7100 | W11: Phone only (no Message / Bid / email on the posting) | X11: Stops: (blank on board)
A12: L8 | B12: Whitewater Freight Inc | C12: Pandora, OH | D12: 139 | E12: Easton, ME | F12: Sep 8 | H12: 1122 | I12: 21h 29m | J12: Flatbed (Hot shot) | K12: LTL | L12: 15 | M12: 750 | N12: 1850 | O12: 1.65 | S12: 0640725 | T12: PARTIAL | U12: loads@whitewaterfreight.com | V12: (812) 637-1720 | W12: Phone + Email + Message (no Bid) | X12: PARTIAL LOAD
A13: L9 | B13: Fifth Wheel Freight | C13: Fort Wayne, IN | D13: 153 | E13: Cedar Point, KS | F13: Sep 8 | G13: 12:00 PM | H13: 758 | I13: 14h 26m | J13: Flatbed (Hot shot) | K13: LTL | L13: 14 | M13: 6033 | N13: 1400 | O13: 1.85 | S13: 757767 | T13: Dispatch (ext. 8550) | V13: (616) 965-7277 | W13: Phone only (no Message / Bid / email on the posting) | X13: CALL / TEXT ext 8550 with any questions. Load must be fully secured before and upon delivery. Driver must accept MacroPoint.
A14: L10 | B14: Freightwatch, LLC | C14: Lexington, OH | D14: 146 | E14: Channahon, IL | F14: Sep 9 | H14: 367 | I14: 7h 04m | J14: Flatbed (Hot shot) | K14: TL | M14: 4700 | N14: 800 | O14: 2.18 | P14: 1287 | Q14: 3.51 | R14: STEEL STAIR SYSTEM | S14: 111676 | T14: Dispatch | U14: quotes+123lb@freightwatchlogistics.com | V14: (419) 845-5250 | W14: Phone + Email + Message + BID | X14: No load note posted. Delivery Sep 10. LENGTH IS BLANK on the posting - must be asked.
B16: Deadhead is the mileage 123Loadboard showed next to each origin, i.e. distance from the search origin (New Richmond, OH 45157). Blank Length / Weight on L2 is genuinely blank on the board - it was not filled in.

Sheet BROKER CRM
A1: BROKER CRM - who they are, what they said, when to chase
A2: History below is taken from the recorded 22-25 Aug 2026 calls. Blank = genuinely unknown, not assumed. Blue cells are yours to keep updating.
A4: Broker | B4: Priority | C4: Phone | D4: Extension | E4: Email | F4: Named contacts | G4: Location | H4: Time zone | I4: Loads on this board | J4: Times contacted | K4: Last contacted | L4: Days since | M4: Follow-up due | N4: Chase status | O4: 180-day new-authority rule? | P4: What they actually said last time (verbatim where recorded) | Q4: Why this broker matters | R4: NEXT ACTION | S4: Outcome of your call (fill in) | T4: Notes (fill in)
A5: Freightwatch, LLC | B5: LOW until Aug 2027 | C5: (419) 845-5250 | E5: quotes+123lb@freightwatchlogistics.com | F5: Dispatch | G5: North-central Ohio (419) | H5: Eastern | I5: L10 | J5: 0 | L5: =IF(K5="","never",TODAY()-DATEVALUE(K5)) -> never | M5: =IF(K5="","today",DATEVALUE(K5)+3) -> today | N5: Blocked - authority age | O5: 1 YEAR - BLOCKED until ~7 Aug 2027 | Q5: 8 Sep, by phone: they do not work with carriers under one year in business. Munster's authority was granted 7 Aug 2026, so this door does not open until roughly 7 Aug 2027 - worse than the 180-day rule. The load itself was the best on the board, which is exactly why this hurts. Nothing to fix and nothing to negotiate; it is a company policy, not a price. Historical note only: posted the only Sep 9 pickup on the board and it starts 146 mi from home, runs into the Chicago metro, and pays against a $1,287 Rate Check. Ohio-based, so same time zone and likely running regional freight this truck can repeat. Accepts Message AND Bid on the board, which means they book off the board rather than off a compliance packet. | R5: Nothing until Aug 2027. Do not spend more calls here. Diarise it and move on.
A6: Fifth Wheel Freight | B6: HIGHEST | C6: (616) 965-7277 | D6: ext 8530 (Huntington WV load) / ext 8550 (Fort Wayne IN load) | F6: Dispatch | G6: Grand Rapids, MI area | H6: Eastern | I6: L6, L9 | J6: 2 | K6: 2026-08-24 | L6: =IF(K6="","never",TODAY()-DATEVALUE(K6)) -> 15 | M6: =IF(K6="","today",DATEVALUE(K6)+3) -> 46261 | N6: Awaiting callback | O6: UNKNOWN - never asked | P6: 24 Aug (call 183, 2:19): reached a LIVE person, was transferred to carrier compliance, held, then dropped to voicemail. Left the Monday-capacity message plus a Highway invite. No callback ever came. A second call was queued for 25 Aug 08:25 (id 222) - its outcome was never recorded. | Q6: Identified 22 Aug as the broker posting the most Munster-sized hotshot freight (South Point OH, Mason MI, Wheeling IL, New Ross IN). Two of the ten loads on the board are theirs. This is the relationship worth building first. | R6: Call ext 8530 about L6. Ask the 180-day question in the first 30 seconds, then register the truck's specs with them permanently.
A7: Transportation Express American Motorways Inc. | B7: HIGH | C7: (402) 564-6375 | F7: Dispatch | G7: Nebraska | H7: Central | I7: L1 | J7: 2 | K7: 2026-08-24 | L7: =IF(K7="","never",TODAY()-DATEVALUE(K7)) -> 15 | M7: =IF(K7="","today",DATEVALUE(K7)+3) -> 46261 | N7: Callback owed BY US | O7: UNKNOWN - never asked | P7: 24 Aug (call 198, 0:16): a human answered and immediately said "Can you have a live person call me?" A callback was promised within ten minutes and NEVER MADE. Before that, 22 Aug (call 194, 0:33): voicemail about a Stow -> Tipp City flatbed partial - a thin message with no truck specs and no rate. | Q7: The only broker on this board that explicitly asked for a human and got silence. That is a repairable relationship and an open door - but it gets worse every day it is left. | R7: Call and open by owning the missed callback. Then ask the rate on L1 (it is not posted) and the 180-day question.
A8: Joe Tex, Inc. | B8: LOW until Feb 2027 | C8: (903) 537-7100 | F8: Angie | G8: East Texas (903) | H8: Central | I8: L7 | J8: 2 | K8: 2026-08-24 | L8: =IF(K8="","never",TODAY()-DATEVALUE(K8)) -> 15 | M8: =IF(K8="","today",DATEVALUE(K8)+3) -> 46261 | N8: Blocked - authority age | O8: 6 MONTHS - blocked until ~7 Feb 2027 | P8: 24 Aug (call 185, 1:09): stuck in the IVR. The menu is "press one for brokerage dispatch" and the call ended there - a human was never reached. A second attempt was queued for 25 Aug 09:00 (id 224); its outcome was never recorded. | Q8: Board now shows a named contact - Angie - which is exactly what beats an IVR. NOTE: prior call notes say "Joe Tex LLC" while the board says "Joe Tex, Inc." - treat them as the same company only once someone confirms it on the phone. | R8: 8 Sep, finally reached a human: they require 6 months in business. Munster clears that around 7 Feb 2027. Nothing to do until then - diarise it. Worth noting the IVR was never the real obstacle; the onboarding rule was, and two earlier calls died in the menu before anyone could say so.
A9: Venture Connect LLC (Venture Logistics) | B9: LOW for now | C9: (317) 854-5027 | E9: loadpostings+123lb@venturelogistics.com | F9: Dispatch | G9: Indianapolis, IN | H9: Eastern | I9: L3, L4 | J9: 3 | K9: 2026-09-08 | L9: =IF(K9="","never",TODAY()-DATEVALUE(K9)) -> 0 | M9: =IF(K9="","today",DATEVALUE(K9)+3) -> 46276 | N9: Blocked - insurance policy | O9: REFUSED 8 Sep - will not set up a carrier insured by PROGRESSIVE | P9: 8 Sep, TWO replies on L3, both from loads@ventureconnect.mail.parade.ai. First: "I've got some lower offers. If you can get to $1400, it's yours!" Second, after we countered at $1,600 with the HOS problem spelled out: "Load's getting a lot of attention. $1400 should get you the load." Both replies repeated the SAME confirmation block verbatim (30 FT HOTSHOT, Shelbyville 09/08 1200 EDT, Stanhope 09/09 0800-1000 EDT, 1,095 lb, tracking required) and BOTH ignored every question: no fine amount, no answer on 27 ft overhang, no answer on the new-authority rule, no movement on the pickup time. The mail domain is Parade, a broker automation platform - treat this thread as an automated quoting bot, not a person. THEN a fourth message, on L4 this time: "This one is getting a lot of interest. $900 should get you the load." That one DID carry new and useful detail - equipment 20 FT HOTSHOT, pickup Shelbyville 09/08 between 1100 and 1400 EDT, delivery Selmer TN 09/09 between 0800 and 1000 CDT, and no tracking requirement. So the bot will hand over appointment data; it just will not negotiate anything except price. | Q9: Posts hotshot construction freight sized almost exactly to a 30 ft deck, and the L3 posting sits $1,835 under 123LB's own Rate Check. Their jobsite work runs under the broker name TRANSCOR. Board offers both Message and Bid, so they book off the board rather than off a compliance packet. | R9: BOTH LOADS ARE DEAD. On 8 Sep by phone they said they cannot set Munster up because the insurance is Progressive - so the whole night of rate negotiation was on loads this carrier was never eligible to haul. Nothing to counter. If it is ever worth re-opening, ask whether it is Progressive specifically or the age of the authority, whether a higher limit or endorsement fixes it, and for their approved-insurer list. HISTORICAL: If L3 is still wanted, PHONE (317) 854-5027 and ask a human for two things only: move the pickup to 1100 EDT (or delivery to 1100-1200), and the fine amount in writing. Otherwise decline politely and use the call to ask for Selmer TN and to get registered for future 30 ft hotshot freight - they told us twice they are shopping for exactly this equipment, which is the real prize here.
A10: Warren Transport, Inc. | B10: MEDIUM | C10: (800) 206-7980 | E10: loads@warrentransport.com | F10: Angie, Erica, Michele, Ken | G10: Iowa | H10: Central | I10: L2 | J10: 0 | L10: =IF(K10="","never",TODAY()-DATEVALUE(K10)) -> never | M10: =IF(K10="","today",DATEVALUE(K10)+3) -> today | N10: New - parked | O10: UNKNOWN - never contacted | Q10: NOT the same company as WARREN'S COURIER AGENCY (that is a LoadBoot carrier - do not mix them up). Their L2 to Idaho is the best gross on the board at $4,818 market, but the length and weight fields are blank and it breaks the weekend-home rule. | R10: Low priority this week. Worth one email to ask what length and weight L2 actually is, and whether they run smaller regional flatbed freight out of Indiana.
A11: Whitewater Freight Inc | B11: MEDIUM | C11: (812) 637-1720 | E11: loads@whitewaterfreight.com | F11: PARTIAL (as listed on the board) | G11: Indiana (812) | H11: Eastern | I11: L8 | J11: 0 | L11: =IF(K11="","never",TODAY()-DATEVALUE(K11)) -> never | M11: =IF(K11="","today",DATEVALUE(K11)+3) -> today | N11: New | O11: UNKNOWN - never contacted | Q11: Posts PARTIAL loads specifically, which is precisely the freight a 30 ft deck at 9,000 lbs wants. Today's one is priced wrong and goes to a dead-end market, but the broker type is a good long-term match. | R11: Skip L8. Send one email introducing the truck and asking to be added to their partial-freight list for Midwest and South-East lanes.
A12: Fenichey LLC | B12: LOW | C12: (475) 445-2870 | E12: boardresponse+123lb@fenichey.com | F12: Dispatch | G12: Connecticut (475) | H12: Eastern | I12: L5 | J12: 0 | L12: =IF(K12="","never",TODAY()-DATEVALUE(K12)) -> never | M12: =IF(K12="","today",DATEVALUE(K12)+3) -> today | N12: New - poor fit | O12: UNKNOWN - never contacted | Q12: Their L5 demands a dedicated 48 or 53 ft stepdeck with full tarping - freight this truck physically cannot take. Pays well ($3.34/mi) but for a different truck. | R12: No call on L5. Optional single email asking whether they ever post 30 ft / 9,000 lb partials.
A14: KNOWN FROM PRIOR CALLS - not on today's board, but do not lose this
A15: Broker | B15: Standing | C15: What they said | D15: Next action
A16: Sureway / ATS | B16: HARD BLOCK until approx 3 Feb 2027 | C16: 24 Aug (call 186, 2:51): Trish -> carrier compliance (Misty). Verbatim: "We cannot use this company. We have a hundred and eighty day rule of new authority, and it was granted eight seven twenty twenty six." Also said a Highway packet does NOT roll over for a new authority.
A17: Tennessee Steel Haulers | B17: Voicemail only, no callback | C17: 24 Aug (call 184, 4:05): IVR plus a long hold through a recorded newsletter, then voicemail. Left the E1687595 message asking whether a 30 ft deck works. No callback. Another call was queued 25 Aug 08:00 (id 223); outcome never recorded.
A18: Zeal Logistics | B18: Warren's truck, not Justin's | C18: 24 Aug (call 203, 6:36): their agent looped eight times on "I'm not finding you in the system" against MC 99849375 (the FMCSA census had not caught up - it has now). Eventually offered Savannah GA -> Huntsville AL at 23,000 lbs, which was correctly refused as far over capacity. The transfer to a colleague dropped.

Sheet CALL LOG
A1: CALL LOG - append a row every time you touch a broker
A2: Rows 5-11 are the real recorded history from 22-25 Aug 2026. Everything from row 12 down is yours. Never delete a row - the history is the asset.
A4: Date | B4: Time (ET) | C4: Broker | D4: Load ID | E4: Direction | F4: Channel | G4: Who you spoke to | H4: Duration | I4: Outcome | J4: What was said - their words | K4: What we committed to | L4: Next step | M4: Next step due
A5: 2026-08-22 | C5: Transportation Express American Motorways Inc. | E5: Outbound | F5: Phone | G5: Voicemail | H5: 0:33 | I5: Voicemail left | J5: Voicemail only. The message was thin: "calling about your Stow to Tipp City flatbed partial... just checking if that's still available... please call me back at this number." No truck specs, no rate, no email address given. | K5: Nothing concrete. | L5: Superseded by the 24 Aug call.
A6: 2026-08-24 | C6: Tennessee Steel Haulers | E6: Outbound | F6: Phone | G6: Voicemail (after IVR + hold) | H6: 4:05 | I6: Voicemail left | J6: IVR plus a long hold through a recorded newsletter, then voicemail. Left the E1687595 message asking whether a 30 ft deck works. No callback. | K6: Asked them to call back. | L6: One more attempt - lead with the 180-day question.
A7: 2026-08-24 | C7: Fifth Wheel Freight | E7: Outbound | F7: Phone | G7: Live person -> compliance -> voicemail | H7: 2:19 | I7: Voicemail left | J7: Reached a live person, was transferred to carrier compliance, held, then dropped into voicemail. Left the Monday-capacity message and a Highway invite. No callback. | K7: Asked them to call back. | L7: Call ext 8530 about L6 and register truck specs.
A8: 2026-08-24 | C8: Joe Tex, Inc. | E8: Outbound | F8: Phone | G8: Nobody - stuck in IVR | H8: 1:09 | I8: Stuck in IVR | J8: Never reached a human. Their menu is "press one for brokerage dispatch" and the call ended there. | K8: Nothing. | L8: Dial and ask for Angie by name instead of working the menu.
A9: 2026-08-24 | C9: Sureway / ATS | E9: Outbound | F9: Phone | G9: Trish -> Misty (carrier compliance) | H9: 2:51 | I9: Rejected - 180 day rule | J9: Verbatim: "We cannot use this company. We have a hundred and eighty day rule of new authority, and it was granted eight seven twenty twenty six." Also confirmed a Highway packet does NOT roll over for a new authority. | K9: Nothing - clean rejection. | L9: Do not call again until approx 3 Feb 2027. | M9: 2027-02-03
A10: 2026-08-24 | C10: Transportation Express American Motorways Inc. | E10: Outbound | F10: Phone | G10: A human (name not captured) | H10: 0:16 | I10: Callback promised | J10: The human answered and immediately said: "Can you have a live person call me?" | K10: A callback within ten minutes. IT WAS NEVER MADE. | L10: Call them. Open by owning the missed callback.
A11: 2026-08-24 | C11: Zeal Logistics | E11: Outbound | F11: Phone | G11: Agent (name not captured) | H11: 6:36 | I11: Spoke - not a fit | J11: Looped eight times on "I'm not finding you in the system" against MC 99849375 (FMCSA census lag - since resolved). Offered Savannah GA -> Huntsville AL at 23,000 lbs, refused as far over capacity. Transfer to a colleague dropped. | K11: Asked them for lighter freight. | L11: Re-approach for Warren's truck, not Justin's.
A12: 2026-08-25 | B12: 08:00 | C12: Tennessee Steel Haulers | E12: Outbound | F12: Phone | I12: UNKNOWN - not recorded | J12: Call was queued (id 223). Its outcome was never recorded - genuinely unknown. | L12: Confirm whether this call ever ran.
A13: 2026-08-25 | B13: 08:25 | C13: Fifth Wheel Freight | E13: Outbound | F13: Phone | I13: UNKNOWN - not recorded | J13: Call was queued (id 222). Its outcome was never recorded - genuinely unknown. | L13: Confirm whether this call ever ran.
A14: 2026-08-25 | B14: 09:00 | C14: Joe Tex, Inc. | E14: Outbound | F14: Phone | I14: UNKNOWN - not recorded | J14: Call was queued (id 224). Its outcome was never recorded - genuinely unknown. | L14: Confirm whether this call ever ran.
A15: 2026-09-08 | C15: Venture Connect LLC | D15: L3 | E15: Outbound | F15: 123LB Message | G15: Dispatch | I15: Emailed only | J15: Offer sent on ref 2177463-2099008 at $2,400, with the three questions (can it roll to 9/9, is 27 ft total with no overhang, what is the late-delivery fine). The exact wording that went out is not recorded here. | K15: Offered to cover at $2,400. | L15: See their reply on the next row.
A16: 2026-09-08 | C16: Venture Connect LLC | D16: L3 | E16: Inbound | F16: Email | G16: Dispatch (loads@ventureconnect.mail.parade.ai) | I16: Rate too low | J16: Verbatim: "I've got some lower offers. If you can get to $1400, it's yours!" Then re-confirmed: Equipment 30 FT HOTSHOT; origin Shelbyville IN 09/08 at 1200 EDT; destination Stanhope NJ 09/09 between 0800 and 1000 EDT; 1,095 lb; NO TARPS; TRANSCOR check-in; hard hat / hi-viz / closed-toe shoes; Tracking Required True; FINES FOR LATE DELIVERY (amount NOT stated). Did not move the pickup and did not answer the overhang or new-authority questions. | K16: Nothing yet - no acceptance was given. | L16: Counter at $1,600 conditional on the pickup moving to 1100 EDT (or delivery to 1100-1200) AND the fine amount in writing. Walk at $1,500. | M16: 2026-09-08
A17: 2026-09-08 | C17: Venture Connect LLC | D17: L3 | E17: Inbound | F17: Email | G17: Automated (parade.ai) | I17: Rate too low | J17: Second reply, verbatim: "Load's getting a lot of attention. $1400 should get you the load." Then the IDENTICAL confirmation block again. Still no fine amount, still no movement on the 1200 pickup, still no answer on overhang or new-authority. Two identical auto-confirmations plus zero answers = this is a bot on Parade, not a person reading the questions. | K17: Nothing. No acceptance given. | L17: Stop emailing. Phone (317) 854-5027 for a human, or decline and move to L10. | M17: 2026-09-08
A18: 2026-09-08 | C18: Venture Connect LLC | D18: L3 | E18: Inbound | F18: Email | G18: Automated (parade.ai) | I18: Rate too low | J18: THIRD reply, verbatim: "Can you do any better?" - and the IDENTICAL confirmation block for the third time. It is now asking US to come down, having answered nothing. Three price-only messages, three identical auto-confirmations, zero answers to the fine amount, the overhang question, the new-authority question or the pickup time. This is an automated price ratchet: it will keep asking for a better number and it will never move the clock. | K18: Nothing. No acceptance given. | L18: Do not bid against yourself. Hold $1,600 in one short line, or walk. Phone (317) 854-5027 if L3 is still wanted. | M18: 2026-09-08
A19: 2026-09-08 | C19: Venture Connect LLC | D19: L4 | E19: Inbound | F19: Email | G19: Automated (parade.ai) | I19: Rate too low | J19: On the Selmer TN load: "This one is getting a lot of interest. $900 should get you the load." Unlike the three L3 replies, this one carried NEW detail worth having: Equipment 20 FT HOTSHOT; origin Shelbyville IN 09/08 between 1100 and 1400 EDT (a three-hour window, not a fixed time); destination Selmer TN 09/09 between 0800 and 1000 CDT; 1,000 lb; NO TARPS; TRANSCOR check-in; PPE. NO tracking requirement stated. Fine amount still not given. | K19: Nothing. No acceptance given. | L19: Counter once at $1,150 (floor $1,025) and ask the fine amount. The schedule on this one works - it is the better of their two loads. | M19: 2026-09-08
A20: 2026-09-08 | C20: Venture Connect LLC | D20: L4 | E20: Inbound | F20: Email | G20: Automated (parade.ai) | I20: Rate too low | J20: Answer to our $1,150: "I've got other offers lower than that. If you can meet me at $900 it's yours!" Same confirmation block for the fifth time. STILL no fine amount - that question has now been asked four times across both loads and never answered. Note the pressure lines are templated: L3 got "getting a lot of attention", L4 got "getting a lot of interest" and now "other offers lower than that" - none of it is verifiable and none of it should move the number. | K20: Nothing. No acceptance given. | L20: Final call: either counter $1,025 once (exact $2.00/mi all-in break-even) or take $900 as a deliberate first-load decision. Get the FINE AMOUNT before agreeing to any price. | M20: 2026-09-08
A21: 2026-09-08 | B21: ~05:30 | C21: Venture Connect LLC | D21: L3 | E21: Outbound | F21: Phone | G21: AI screener -> human front desk | I21: Spoke - not a fit | J21: Called (317) 854-5027. An AI answered FIRST, took all the details, then transferred to a human front desk. The front desk confirmed the pickup is 8 Sep and said they do not have this information, call back after 7 AM. So the phone line is screened by AI too, and the person reachable at this hour has neither the fine amount nor the authority to move an appointment. | K21: Nothing agreed. | L21: Call back at 07:00 EDT and ask for someone who can change an appointment and quote the fine. | M21: 2026-09-08
A22: 2026-09-08 | B22: ~05:40 | C22: Freightwatch / Fifth Wheel / Joe Tex / Transportation Express | E22: Outbound | F22: Phone | I22: No answer | J22: Round of calls to the other brokers - nobody picked up. Expected: it is 05:40 EDT and no brokerage office is open. Fifth Wheel (MI) and Freightwatch (OH) are Eastern, Joe Tex (TX) and Transportation Express (NE) are Central, so Joe Tex was rung at 04:40 their time. Not a dead-number problem - just the hour. | K22: Nothing. | L22: Re-dial on the schedule in the CALL PLAN tab, staggered by each broker's own time zone. | M22: 2026-09-08
A23: 2026-09-08 | B23: 07:00 | C23: Venture Connect LLC | D23: L4 | E23: Outbound | F23: Phone | I23: UNKNOWN - not recorded | J23: TO DO NOW. (317) 854-5027. Open with: I called last night, got your AI, then a front desk who did not have the information and said call after 7 - so I need someone who can change an appointment and quote me a fine amount. TWO QUESTIONS: (1) what is the AMOUNT of the late-delivery fine? (2) can the Selmer pickup be at the 1100 end of your window? THEN: $1,025 and it is covered. | L23: ASK $1,025. FLOOR $1,025 - do not go below. No fine amount = no load. | M23: 2026-09-08
A24: 2026-09-08 | B24: 07:30 | C24: Freightwatch, LLC | D24: L10 | E24: Outbound | F24: Phone | I24: UNKNOWN - not recorded | J24: TO DO NOW. (419) 845-5250. Send the board MESSAGE and place the $1,300 BID before dialling. FIRST QUESTION: what is the overall LENGTH of the steel stair system? Over 30 ft = stop, thank them, done. Then the new-authority rule, then $1,300. | L24: ASK $1,300. WALK $1,050. Picks up tomorrow so it is not on today's clock. | M24: 2026-09-08
A25: 2026-09-08 | B25: 08:00 | C25: Fifth Wheel Freight | D25: L6 + L9 | E25: Outbound | F25: Phone | I25: UNKNOWN - not recorded | J25: ONE call, BOTH loads. (616) 965-7277 - ext 8530 for L6 Huntington WV to Sparrows Point MD, then ext 8550 for L9 Fort Wayne to Cedar Point KS. Accept MacroPoint on L6. The real goal is getting the truck registered on their list. | L25: L6 ask $1,300 walk $1,075. L9 ask $2,000 walk $1,850. | M25: 2026-09-08
A26: 2026-09-08 | B26: 08:00 | C26: Whitewater Freight Inc | E26: Outbound | F26: Phone | I26: UNKNOWN - not recorded | J26: Low priority. (812) 637-1720. Not about L8 - just get on their partial-freight list for Midwest and South-East lanes. | L26: No offer. Relationship call only. | M26: 2026-09-08
A27: 2026-09-08 | B27: 09:00 | C27: Transportation Express American Motorways Inc. | D27: L1 | E27: Outbound | F27: Phone | I27: UNKNOWN - not recorded | J27: THE REPAIR CALL. (402) 564-6375 - Nebraska, so 08:00 their time. Open by owning the missed 24 Aug callback: someone there asked for a live person and never got one. Then ask the rate on L1 - it is not posted - and mention it only uses 4 ft of a 30 ft deck, so a second partial could ride along. | L27: ASK $1,300. WALK $1,150. | M27: 2026-09-08
A28: 2026-09-08 | B28: 09:00 | C28: Joe Tex, Inc. | D28: L7 | E28: Outbound | F28: Phone | I28: UNKNOWN - not recorded | J28: ASK FOR ANGIE BY NAME - (903) 537-7100. Two previous calls died in their IVR; working the menu has already failed twice. Rate on L7 is not posted, and confirm 8,000 lb is the real weight (ceiling is 9,000). Also confirm whether Joe Tex LLC and Joe Tex, Inc. are the same company. | L28: ASK $850. WALK $675. | M28: 2026-09-08
A29: 2026-09-08 | B29: 09:00 | C29: Warren Transport, Inc. | D29: L2 | E29: Outbound | F29: Phone | I29: UNKNOWN - not recorded | J29: Lowest priority. (800) 206-7980, Iowa so 08:00 their time. One question only: what length and weight is ref 1181425 actually? Both fields are blank on the posting. | L29: No offer - the Idaho run breaks the weekend-home rule anyway. | M29: 2026-09-08
A30: 2026-09-08 | B30: ~07:45 | C30: Freightwatch, LLC | D30: L10 | E30: Outbound | F30: Phone | G30: Reached a person | I30: Rejected - other | J30: BLOCKED ON AUTHORITY AGE. They said they do not work with carriers who have been in business under one year. Munster's authority was granted 7 Aug 2026, so this opens around 7 Aug 2027. This is a company policy, not a rate or an equipment question - the length of the stair system never even came up. The best-ranked load on the board, lost to something no negotiation touches. | K30: Nothing. | L30: Nothing until Aug 2027. Diarise and stop calling. | M30: 2027-08-07
A31: 2026-09-08 | B31: ~07:50 | C31: UNCONFIRMED - which broker? | E31: Outbound | F31: Phone | I31: Rejected - other | J31: A broker said they cannot set Munster up because the insurance is PROGRESSIVE. WHICH BROKER SAID THIS IS NOT YET RECORDED - fill it in. Context worth keeping: Progressive is one of the largest US commercial trucking insurers and has no flatbed or tarped-freight exclusion, so this is that broker's own approved-insurer policy, not a defect in the cover. It is also commonly a proxy for "this is a new authority", which is the wall we keep hitting. Callback attempted, no answer. | K31: Nothing. | L31: Ask them: is it Progressive specifically or the age of our authority? Any limit or endorsement that fixes it? Can they send their approved-insurer list? | M31: 2026-09-08
A32: 2026-09-09 | B32: 08:15 | C32: Fifth Wheel Freight | D32: L6 | E32: Outbound | F32: Phone | G32: Ask for ext 8530 | H32: 3:40 | I32: Spoke - interested | J32: EXAMPLE ROW - overwrite it. Type what they actually said, in their words. | K32: What you promised them and by when. | L32: The single next thing to do. | M32: 2026-09-10

Sheet CALL SCRIPTS
A1: CALL SCRIPTS - drafts for you to say and send
A2: Nothing here has been sent anywhere. Every call and every email goes out from you. Scripts are in English because that is what the broker hears.
B4: UNIVERSAL OPENER - use this on every single call
B5: Line 1 - who | C5: Hi, this is Yaseen calling for Munster Logistics, MC 84057665 - we run a 30 foot hotshot gooseneck out of New Richmond, Ohio.
B6: Line 2 - the 180-day question, FIRST | C6: Before I take up your time - do you have a new-authority rule, and how many days is it? Our authority was granted 7 August this year. WHY THIS GOES FIRST: on 24 Aug, Sureway/ATS put four minutes of hold into this exact conversation and then said 'we have a 180 day rule of new authority and it was granted 8-7-2026.' Asking up front turns that into a ten-second answer. IF THEY SAY 180 DAYS: 'Understood, thank you - that puts us at early February. Can I send you our packet now so we are already set up when that date hits?' Then log it in BROKER CRM and hang up. Do not argue it.
B7: Line 3 - is it still there | C7: I'm calling on your load [REF #] from [ORIGIN] to [DESTINATION]. Two things: is it still available, and can it pick up tomorrow, Wednesday the 9th? My truck is empty from tomorrow morning.
B8: Line 4 - the truck, said out loud | C8: Munster Logistics, MC eight four zero five seven six six five. Thirty foot gooseneck deck, one hundred and two inches wide, nine thousand pounds max payload. Tarps, Grade eighty chains and binders, straps and mega ramps on board. One million auto liability, one hundred thousand cargo. Based New Richmond, Ohio.
B9: Line 5 - the rate | C9: IF A RATE IS POSTED: 'I can do it at [TARGET ASK from the SHORTLIST tab]. That covers the [DH] miles of deadhead to get to you plus the loaded run.' IF NO RATE IS POSTED: 'What are you paying on it?' - then stay quiet and let them answer first. Never open at the walk-away number. The walk-away column is the point where you politely stop, not where you start.
B10: Line 6 - always close with this | C10: Even on a no: 'Understood. Can I email you our capacity so I'm on your list? We're a 30 foot deck, 9,000 pounds, based in Cincinnati - we do a lot of partials, and we're empty most weekday mornings.' Then get the email address and log it.
B12: IF YOU GET VOICEMAIL - say all of this, not half of it
